{
 "cells": [
  {
   "cell_type": "code",
   "execution_count": 1,
   "metadata": {},
   "outputs": [],
   "source": [
    "from keras.models import load_model\n",
    "from sklearn.metrics import classification_report, confusion_matrix\n",
    "from keras.applications.vgg16 import VGG16\n",
    "from keras.layers import Input, Lambda, Dense, Flatten\n",
    "from keras.models import Model, load_model\n",
    "from keras.preprocessing.image import ImageDataGenerator\n",
    "import numpy as np"
   ]
  },
  {
   "cell_type": "code",
   "execution_count": 2,
   "metadata": {},
   "outputs": [
    {
     "name": "stdout",
     "output_type": "stream",
     "text": [
      "Found 624 images belonging to 2 classes.\n"
     ]
    }
   ],
   "source": [
    "test_datagen = ImageDataGenerator(rescale=1./255)\n",
    "test_set = test_datagen.flow_from_directory('chest_xray/test',\n",
    "                                            target_size=(224, 224),\n",
    "                                            batch_size=32,\n",
    "                                            class_mode='categorical', \n",
    "                                            shuffle=False)  # Ensure that it doesn't shuffle the data"
   ]
  },
  {
   "cell_type": "code",
   "execution_count": 3,
   "metadata": {},
   "outputs": [],
   "source": [
    "vgg = VGG16(input_shape=[224,224] + [3], weights='imagenet', include_top=False)\n",
    "for layer in vgg.layers:\n",
    "    layer.trainable = False\n",
    "x = Flatten()(vgg.output)\n",
    "prediction = Dense(2, activation='softmax')(x)\n",
    "model = Model(inputs=vgg.input, outputs=prediction)"
   ]
  },
  {
   "cell_type": "code",
   "execution_count": 4,
   "metadata": {},
   "outputs": [
    {
     "data": {
      "text/plain": [
       "<tensorflow.python.training.tracking.util.CheckpointLoadStatus at 0x203070de460>"
      ]
     },
     "execution_count": 4,
     "metadata": {},
     "output_type": "execute_result"
    }
   ],
   "source": [
    "model.load_weights('training_1/cp.ckpt')"
   ]
  },
  {
   "cell_type": "code",
   "execution_count": 5,
   "metadata": {},
   "outputs": [],
   "source": [
    "model.compile(optimizer='adam', loss='categorical_crossentropy', metrics=['accuracy'])"
   ]
  },
  {
   "cell_type": "code",
   "execution_count": 6,
   "metadata": {},
   "outputs": [
    {
     "ename": "NotFoundError",
     "evalue": "Graph execution error:\n\nDetected at node 'model/block1_conv1/Conv2D' defined at (most recent call last):\n    File \"c:\\Users\\Biki\\anaconda3\\envs\\venv1\\lib\\runpy.py\", line 197, in _run_module_as_main\n      return _run_code(code, main_globals, None,\n    File \"c:\\Users\\Biki\\anaconda3\\envs\\venv1\\lib\\runpy.py\", line 87, in _run_code\n      exec(code, run_globals)\n    File \"c:\\Users\\Biki\\anaconda3\\envs\\venv1\\lib\\site-packages\\ipykernel_launcher.py\", line 17, in <module>\n      app.launch_new_instance()\n    File \"c:\\Users\\Biki\\anaconda3\\envs\\venv1\\lib\\site-packages\\traitlets\\config\\application.py\", line 976, in launch_instance\n      app.start()\n    File \"c:\\Users\\Biki\\anaconda3\\envs\\venv1\\lib\\site-packages\\ipykernel\\kernelapp.py\", line 712, in start\n      self.io_loop.start()\n    File \"c:\\Users\\Biki\\anaconda3\\envs\\venv1\\lib\\site-packages\\tornado\\platform\\asyncio.py\", line 199, in start\n      self.asyncio_loop.run_forever()\n    File \"c:\\Users\\Biki\\anaconda3\\envs\\venv1\\lib\\asyncio\\base_events.py\", line 596, in run_forever\n      self._run_once()\n    File \"c:\\Users\\Biki\\anaconda3\\envs\\venv1\\lib\\asyncio\\base_events.py\", line 1890, in _run_once\n      handle._run()\n    File \"c:\\Users\\Biki\\anaconda3\\envs\\venv1\\lib\\asyncio\\events.py\", line 80, in _run\n      self._context.run(self._callback, *self._args)\n    File \"c:\\Users\\Biki\\anaconda3\\envs\\venv1\\lib\\site-packages\\ipykernel\\kernelbase.py\", line 504, in dispatch_queue\n      await self.process_one()\n    File \"c:\\Users\\Biki\\anaconda3\\envs\\venv1\\lib\\site-packages\\ipykernel\\kernelbase.py\", line 493, in process_one\n      await dispatch(*args)\n    File \"c:\\Users\\Biki\\anaconda3\\envs\\venv1\\lib\\site-packages\\ipykernel\\kernelbase.py\", line 400, in dispatch_shell\n      await result\n    File \"c:\\Users\\Biki\\anaconda3\\envs\\venv1\\lib\\site-packages\\ipykernel\\kernelbase.py\", line 724, in execute_request\n      reply_content = await reply_content\n    File \"c:\\Users\\Biki\\anaconda3\\envs\\venv1\\lib\\site-packages\\ipykernel\\ipkernel.py\", line 383, in do_execute\n      res = shell.run_cell(\n    File \"c:\\Users\\Biki\\anaconda3\\envs\\venv1\\lib\\site-packages\\ipykernel\\zmqshell.py\", line 528, in run_cell\n      return super().run_cell(*args, **kwargs)\n    File \"c:\\Users\\Biki\\anaconda3\\envs\\venv1\\lib\\site-packages\\IPython\\core\\interactiveshell.py\", line 2880, in run_cell\n      result = self._run_cell(\n    File \"c:\\Users\\Biki\\anaconda3\\envs\\venv1\\lib\\site-packages\\IPython\\core\\interactiveshell.py\", line 2935, in _run_cell\n      return runner(coro)\n    File \"c:\\Users\\Biki\\anaconda3\\envs\\venv1\\lib\\site-packages\\IPython\\core\\async_helpers.py\", line 129, in _pseudo_sync_runner\n      coro.send(None)\n    File \"c:\\Users\\Biki\\anaconda3\\envs\\venv1\\lib\\site-packages\\IPython\\core\\interactiveshell.py\", line 3134, in run_cell_async\n      has_raised = await self.run_ast_nodes(code_ast.body, cell_name,\n    File \"c:\\Users\\Biki\\anaconda3\\envs\\venv1\\lib\\site-packages\\IPython\\core\\interactiveshell.py\", line 3337, in run_ast_nodes\n      if await self.run_code(code, result, async_=asy):\n    File \"c:\\Users\\Biki\\anaconda3\\envs\\venv1\\lib\\site-packages\\IPython\\core\\interactiveshell.py\", line 3397, in run_code\n      exec(code_obj, self.user_global_ns, self.user_ns)\n    File \"C:\\temp\\ipykernel_20348\\2353388302.py\", line 1, in <cell line: 1>\n      test_loss, test_accuracy = model.evaluate(test_set, steps=len(test_set), batch_size=2)\n    File \"c:\\Users\\Biki\\anaconda3\\envs\\venv1\\lib\\site-packages\\keras\\utils\\traceback_utils.py\", line 64, in error_handler\n      return fn(*args, **kwargs)\n    File \"c:\\Users\\Biki\\anaconda3\\envs\\venv1\\lib\\site-packages\\keras\\engine\\training.py\", line 1756, in evaluate\n      tmp_logs = self.test_function(iterator)\n    File \"c:\\Users\\Biki\\anaconda3\\envs\\venv1\\lib\\site-packages\\keras\\engine\\training.py\", line 1557, in test_function\n      return step_function(self, iterator)\n    File \"c:\\Users\\Biki\\anaconda3\\envs\\venv1\\lib\\site-packages\\keras\\engine\\training.py\", line 1546, in step_function\n      outputs = model.distribute_strategy.run(run_step, args=(data,))\n    File \"c:\\Users\\Biki\\anaconda3\\envs\\venv1\\lib\\site-packages\\keras\\engine\\training.py\", line 1535, in run_step\n      outputs = model.test_step(data)\n    File \"c:\\Users\\Biki\\anaconda3\\envs\\venv1\\lib\\site-packages\\keras\\engine\\training.py\", line 1499, in test_step\n      y_pred = self(x, training=False)\n    File \"c:\\Users\\Biki\\anaconda3\\envs\\venv1\\lib\\site-packages\\keras\\utils\\traceback_utils.py\", line 64, in error_handler\n      return fn(*args, **kwargs)\n    File \"c:\\Users\\Biki\\anaconda3\\envs\\venv1\\lib\\site-packages\\keras\\engine\\training.py\", line 490, in __call__\n      return super().__call__(*args, **kwargs)\n    File \"c:\\Users\\Biki\\anaconda3\\envs\\venv1\\lib\\site-packages\\keras\\utils\\traceback_utils.py\", line 64, in error_handler\n      return fn(*args, **kwargs)\n    File \"c:\\Users\\Biki\\anaconda3\\envs\\venv1\\lib\\site-packages\\keras\\engine\\base_layer.py\", line 1014, in __call__\n      outputs = call_fn(inputs, *args, **kwargs)\n    File \"c:\\Users\\Biki\\anaconda3\\envs\\venv1\\lib\\site-packages\\keras\\utils\\traceback_utils.py\", line 92, in error_handler\n      return fn(*args, **kwargs)\n    File \"c:\\Users\\Biki\\anaconda3\\envs\\venv1\\lib\\site-packages\\keras\\engine\\functional.py\", line 458, in call\n      return self._run_internal_graph(\n    File \"c:\\Users\\Biki\\anaconda3\\envs\\venv1\\lib\\site-packages\\keras\\engine\\functional.py\", line 596, in _run_internal_graph\n      outputs = node.layer(*args, **kwargs)\n    File \"c:\\Users\\Biki\\anaconda3\\envs\\venv1\\lib\\site-packages\\keras\\utils\\traceback_utils.py\", line 64, in error_handler\n      return fn(*args, **kwargs)\n    File \"c:\\Users\\Biki\\anaconda3\\envs\\venv1\\lib\\site-packages\\keras\\engine\\base_layer.py\", line 1014, in __call__\n      outputs = call_fn(inputs, *args, **kwargs)\n    File \"c:\\Users\\Biki\\anaconda3\\envs\\venv1\\lib\\site-packages\\keras\\utils\\traceback_utils.py\", line 92, in error_handler\n      return fn(*args, **kwargs)\n    File \"c:\\Users\\Biki\\anaconda3\\envs\\venv1\\lib\\site-packages\\keras\\layers\\convolutional\\base_conv.py\", line 250, in call\n      outputs = self.convolution_op(inputs, self.kernel)\n    File \"c:\\Users\\Biki\\anaconda3\\envs\\venv1\\lib\\site-packages\\keras\\layers\\convolutional\\base_conv.py\", line 225, in convolution_op\n      return tf.nn.convolution(\nNode: 'model/block1_conv1/Conv2D'\nNo algorithm worked!  Error messages:\n  Profiling failure on CUDNN engine 1#TC: UNKNOWN: CUDNN_STATUS_EXECUTION_FAILED\nin tensorflow/stream_executor/cuda/cuda_dnn.cc(4031): 'cudnnConvolutionForward( cudnn.handle(), alpha, input_nd_.handle(), input_data.opaque(), filter_.handle(), filter_data.opaque(), conv_.handle(), ToConvForwardAlgo(algo), scratch_memory.opaque(), scratch_memory.size(), beta, output_nd_.handle(), output_data.opaque())'\n  Profiling failure on CUDNN engine 1: UNKNOWN: CUDNN_STATUS_EXECUTION_FAILED\nin tensorflow/stream_executor/cuda/cuda_dnn.cc(4031): 'cudnnConvolutionForward( cudnn.handle(), alpha, input_nd_.handle(), input_data.opaque(), filter_.handle(), filter_data.opaque(), conv_.handle(), ToConvForwardAlgo(algo), scratch_memory.opaque(), scratch_memory.size(), beta, output_nd_.handle(), output_data.opaque())'\n  Profiling failure on CUDNN engine 0#TC: UNKNOWN: CUDNN_STATUS_EXECUTION_FAILED\nin tensorflow/stream_executor/cuda/cuda_dnn.cc(4031): 'cudnnConvolutionForward( cudnn.handle(), alpha, input_nd_.handle(), input_data.opaque(), filter_.handle(), filter_data.opaque(), conv_.handle(), ToConvForwardAlgo(algo), scratch_memory.opaque(), scratch_memory.size(), beta, output_nd_.handle(), output_data.opaque())'\n  Profiling failure on CUDNN engine 0: UNKNOWN: CUDNN_STATUS_EXECUTION_FAILED\nin tensorflow/stream_executor/cuda/cuda_dnn.cc(4031): 'cudnnConvolutionForward( cudnn.handle(), alpha, input_nd_.handle(), input_data.opaque(), filter_.handle(), filter_data.opaque(), conv_.handle(), ToConvForwardAlgo(algo), scratch_memory.opaque(), scratch_memory.size(), beta, output_nd_.handle(), output_data.opaque())'\n  Profiling failure on CUDNN engine 2#TC: UNKNOWN: CUDNN_STATUS_EXECUTION_FAILED\nin tensorflow/stream_executor/cuda/cuda_dnn.cc(4031): 'cudnnConvolutionForward( cudnn.handle(), alpha, input_nd_.handle(), input_data.opaque(), filter_.handle(), filter_data.opaque(), conv_.handle(), ToConvForwardAlgo(algo), scratch_memory.opaque(), scratch_memory.size(), beta, output_nd_.handle(), output_data.opaque())'\n  Profiling failure on CUDNN engine 2: UNKNOWN: CUDNN_STATUS_EXECUTION_FAILED\nin tensorflow/stream_executor/cuda/cuda_dnn.cc(4031): 'cudnnConvolutionForward( cudnn.handle(), alpha, input_nd_.handle(), input_data.opaque(), filter_.handle(), filter_data.opaque(), conv_.handle(), ToConvForwardAlgo(algo), scratch_memory.opaque(), scratch_memory.size(), beta, output_nd_.handle(), output_data.opaque())'\n  Profiling failure on CUDNN engine 4#TC: UNKNOWN: CUDNN_STATUS_EXECUTION_FAILED\nin tensorflow/stream_executor/cuda/cuda_dnn.cc(4031): 'cudnnConvolutionForward( cudnn.handle(), alpha, input_nd_.handle(), input_data.opaque(), filter_.handle(), filter_data.opaque(), conv_.handle(), ToConvForwardAlgo(algo), scratch_memory.opaque(), scratch_memory.size(), beta, output_nd_.handle(), output_data.opaque())'\n  Profiling failure on CUDNN engine 4: UNKNOWN: CUDNN_STATUS_EXECUTION_FAILED\nin tensorflow/stream_executor/cuda/cuda_dnn.cc(4031): 'cudnnConvolutionForward( cudnn.handle(), alpha, input_nd_.handle(), input_data.opaque(), filter_.handle(), filter_data.opaque(), conv_.handle(), ToConvForwardAlgo(algo), scratch_memory.opaque(), scratch_memory.size(), beta, output_nd_.handle(), output_data.opaque())'\n  Profiling failure on CUDNN engine 6#TC: UNKNOWN: CUDNN_STATUS_EXECUTION_FAILED\nin tensorflow/stream_executor/cuda/cuda_dnn.cc(4031): 'cudnnConvolutionForward( cudnn.handle(), alpha, input_nd_.handle(), input_data.opaque(), filter_.handle(), filter_data.opaque(), conv_.handle(), ToConvForwardAlgo(algo), scratch_memory.opaque(), scratch_memory.size(), beta, output_nd_.handle(), output_data.opaque())'\n  Profiling failure on CUDNN engine 6: UNKNOWN: CUDNN_STATUS_EXECUTION_FAILED\nin tensorflow/stream_executor/cuda/cuda_dnn.cc(4031): 'cudnnConvolutionForward( cudnn.handle(), alpha, input_nd_.handle(), input_data.opaque(), filter_.handle(), filter_data.opaque(), conv_.handle(), ToConvForwardAlgo(algo), scratch_memory.opaque(), scratch_memory.size(), beta, output_nd_.handle(), output_data.opaque())'\n  Profiling failure on CUDNN engine 5#TC: UNKNOWN: CUDNN_STATUS_INTERNAL_ERROR\nin tensorflow/stream_executor/cuda/cuda_dnn.cc(4031): 'cudnnConvolutionForward( cudnn.handle(), alpha, input_nd_.handle(), input_data.opaque(), filter_.handle(), filter_data.opaque(), conv_.handle(), ToConvForwardAlgo(algo), scratch_memory.opaque(), scratch_memory.size(), beta, output_nd_.handle(), output_data.opaque())'\n  Profiling failure on CUDNN engine 5: UNKNOWN: CUDNN_STATUS_INTERNAL_ERROR\nin tensorflow/stream_executor/cuda/cuda_dnn.cc(4031): 'cudnnConvolutionForward( cudnn.handle(), alpha, input_nd_.handle(), input_data.opaque(), filter_.handle(), filter_data.opaque(), conv_.handle(), ToConvForwardAlgo(algo), scratch_memory.opaque(), scratch_memory.size(), beta, output_nd_.handle(), output_data.opaque())'\n  Profiling failure on CUDNN engine 7#TC: UNKNOWN: CUDNN_STATUS_EXECUTION_FAILED\nin tensorflow/stream_executor/cuda/cuda_dnn.cc(4031): 'cudnnConvolutionForward( cudnn.handle(), alpha, input_nd_.handle(), input_data.opaque(), filter_.handle(), filter_data.opaque(), conv_.handle(), ToConvForwardAlgo(algo), scratch_memory.opaque(), scratch_memory.size(), beta, output_nd_.handle(), output_data.opaque())'\n  Profiling failure on CUDNN engine 7: UNKNOWN: CUDNN_STATUS_EXECUTION_FAILED\nin tensorflow/stream_executor/cuda/cuda_dnn.cc(4031): 'cudnnConvolutionForward( cudnn.handle(), alpha, input_nd_.handle(), input_data.opaque(), filter_.handle(), filter_data.opaque(), conv_.handle(), ToConvForwardAlgo(algo), scratch_memory.opaque(), scratch_memory.size(), beta, output_nd_.handle(), output_data.opaque())'\n\t [[{{node model/block1_conv1/Conv2D}}]] [Op:__inference_test_function_912]",
     "output_type": "error",
     "traceback": [
      "\u001b[1;31m---------------------------------------------------------------------------\u001b[0m",
      "\u001b[1;31mNotFoundError\u001b[0m                             Traceback (most recent call last)",
      "\u001b[1;32mc:\\Users\\Biki\\.vscode\\Project Files\\.vscode\\Pneumonia-Prediction\\test_eval.ipynb Cell 6\u001b[0m in \u001b[0;36m<cell line: 1>\u001b[1;34m()\u001b[0m\n\u001b[1;32m----> <a href='vscode-notebook-cell:/c%3A/Users/Biki/.vscode/Project%20Files/.vscode/Pneumonia-Prediction/test_eval.ipynb#W5sZmlsZQ%3D%3D?line=0'>1</a>\u001b[0m test_loss, test_accuracy \u001b[39m=\u001b[39m model\u001b[39m.\u001b[39;49mevaluate(test_set, steps\u001b[39m=\u001b[39;49m\u001b[39mlen\u001b[39;49m(test_set), batch_size\u001b[39m=\u001b[39;49m\u001b[39m2\u001b[39;49m)\n",
      "File \u001b[1;32mc:\\Users\\Biki\\anaconda3\\envs\\venv1\\lib\\site-packages\\keras\\utils\\traceback_utils.py:67\u001b[0m, in \u001b[0;36mfilter_traceback.<locals>.error_handler\u001b[1;34m(*args, **kwargs)\u001b[0m\n\u001b[0;32m     65\u001b[0m \u001b[39mexcept\u001b[39;00m \u001b[39mException\u001b[39;00m \u001b[39mas\u001b[39;00m e:  \u001b[39m# pylint: disable=broad-except\u001b[39;00m\n\u001b[0;32m     66\u001b[0m   filtered_tb \u001b[39m=\u001b[39m _process_traceback_frames(e\u001b[39m.\u001b[39m__traceback__)\n\u001b[1;32m---> 67\u001b[0m   \u001b[39mraise\u001b[39;00m e\u001b[39m.\u001b[39mwith_traceback(filtered_tb) \u001b[39mfrom\u001b[39;00m \u001b[39mNone\u001b[39m\n\u001b[0;32m     68\u001b[0m \u001b[39mfinally\u001b[39;00m:\n\u001b[0;32m     69\u001b[0m   \u001b[39mdel\u001b[39;00m filtered_tb\n",
      "File \u001b[1;32mc:\\Users\\Biki\\anaconda3\\envs\\venv1\\lib\\site-packages\\tensorflow\\python\\eager\\execute.py:54\u001b[0m, in \u001b[0;36mquick_execute\u001b[1;34m(op_name, num_outputs, inputs, attrs, ctx, name)\u001b[0m\n\u001b[0;32m     52\u001b[0m \u001b[39mtry\u001b[39;00m:\n\u001b[0;32m     53\u001b[0m   ctx\u001b[39m.\u001b[39mensure_initialized()\n\u001b[1;32m---> 54\u001b[0m   tensors \u001b[39m=\u001b[39m pywrap_tfe\u001b[39m.\u001b[39mTFE_Py_Execute(ctx\u001b[39m.\u001b[39m_handle, device_name, op_name,\n\u001b[0;32m     55\u001b[0m                                       inputs, attrs, num_outputs)\n\u001b[0;32m     56\u001b[0m \u001b[39mexcept\u001b[39;00m core\u001b[39m.\u001b[39m_NotOkStatusException \u001b[39mas\u001b[39;00m e:\n\u001b[0;32m     57\u001b[0m   \u001b[39mif\u001b[39;00m name \u001b[39mis\u001b[39;00m \u001b[39mnot\u001b[39;00m \u001b[39mNone\u001b[39;00m:\n",
      "\u001b[1;31mNotFoundError\u001b[0m: Graph execution error:\n\nDetected at node 'model/block1_conv1/Conv2D' defined at (most recent call last):\n    File \"c:\\Users\\Biki\\anaconda3\\envs\\venv1\\lib\\runpy.py\", line 197, in _run_module_as_main\n      return _run_code(code, main_globals, None,\n    File \"c:\\Users\\Biki\\anaconda3\\envs\\venv1\\lib\\runpy.py\", line 87, in _run_code\n      exec(code, run_globals)\n    File \"c:\\Users\\Biki\\anaconda3\\envs\\venv1\\lib\\site-packages\\ipykernel_launcher.py\", line 17, in <module>\n      app.launch_new_instance()\n    File \"c:\\Users\\Biki\\anaconda3\\envs\\venv1\\lib\\site-packages\\traitlets\\config\\application.py\", line 976, in launch_instance\n      app.start()\n    File \"c:\\Users\\Biki\\anaconda3\\envs\\venv1\\lib\\site-packages\\ipykernel\\kernelapp.py\", line 712, in start\n      self.io_loop.start()\n    File \"c:\\Users\\Biki\\anaconda3\\envs\\venv1\\lib\\site-packages\\tornado\\platform\\asyncio.py\", line 199, in start\n      self.asyncio_loop.run_forever()\n    File \"c:\\Users\\Biki\\anaconda3\\envs\\venv1\\lib\\asyncio\\base_events.py\", line 596, in run_forever\n      self._run_once()\n    File \"c:\\Users\\Biki\\anaconda3\\envs\\venv1\\lib\\asyncio\\base_events.py\", line 1890, in _run_once\n      handle._run()\n    File \"c:\\Users\\Biki\\anaconda3\\envs\\venv1\\lib\\asyncio\\events.py\", line 80, in _run\n      self._context.run(self._callback, *self._args)\n    File \"c:\\Users\\Biki\\anaconda3\\envs\\venv1\\lib\\site-packages\\ipykernel\\kernelbase.py\", line 504, in dispatch_queue\n      await self.process_one()\n    File \"c:\\Users\\Biki\\anaconda3\\envs\\venv1\\lib\\site-packages\\ipykernel\\kernelbase.py\", line 493, in process_one\n      await dispatch(*args)\n    File \"c:\\Users\\Biki\\anaconda3\\envs\\venv1\\lib\\site-packages\\ipykernel\\kernelbase.py\", line 400, in dispatch_shell\n      await result\n    File \"c:\\Users\\Biki\\anaconda3\\envs\\venv1\\lib\\site-packages\\ipykernel\\kernelbase.py\", line 724, in execute_request\n      reply_content = await reply_content\n    File \"c:\\Users\\Biki\\anaconda3\\envs\\venv1\\lib\\site-packages\\ipykernel\\ipkernel.py\", line 383, in do_execute\n      res = shell.run_cell(\n    File \"c:\\Users\\Biki\\anaconda3\\envs\\venv1\\lib\\site-packages\\ipykernel\\zmqshell.py\", line 528, in run_cell\n      return super().run_cell(*args, **kwargs)\n    File \"c:\\Users\\Biki\\anaconda3\\envs\\venv1\\lib\\site-packages\\IPython\\core\\interactiveshell.py\", line 2880, in run_cell\n      result = self._run_cell(\n    File \"c:\\Users\\Biki\\anaconda3\\envs\\venv1\\lib\\site-packages\\IPython\\core\\interactiveshell.py\", line 2935, in _run_cell\n      return runner(coro)\n    File \"c:\\Users\\Biki\\anaconda3\\envs\\venv1\\lib\\site-packages\\IPython\\core\\async_helpers.py\", line 129, in _pseudo_sync_runner\n      coro.send(None)\n    File \"c:\\Users\\Biki\\anaconda3\\envs\\venv1\\lib\\site-packages\\IPython\\core\\interactiveshell.py\", line 3134, in run_cell_async\n      has_raised = await self.run_ast_nodes(code_ast.body, cell_name,\n    File \"c:\\Users\\Biki\\anaconda3\\envs\\venv1\\lib\\site-packages\\IPython\\core\\interactiveshell.py\", line 3337, in run_ast_nodes\n      if await self.run_code(code, result, async_=asy):\n    File \"c:\\Users\\Biki\\anaconda3\\envs\\venv1\\lib\\site-packages\\IPython\\core\\interactiveshell.py\", line 3397, in run_code\n      exec(code_obj, self.user_global_ns, self.user_ns)\n    File \"C:\\temp\\ipykernel_20348\\2353388302.py\", line 1, in <cell line: 1>\n      test_loss, test_accuracy = model.evaluate(test_set, steps=len(test_set), batch_size=2)\n    File \"c:\\Users\\Biki\\anaconda3\\envs\\venv1\\lib\\site-packages\\keras\\utils\\traceback_utils.py\", line 64, in error_handler\n      return fn(*args, **kwargs)\n    File \"c:\\Users\\Biki\\anaconda3\\envs\\venv1\\lib\\site-packages\\keras\\engine\\training.py\", line 1756, in evaluate\n      tmp_logs = self.test_function(iterator)\n    File \"c:\\Users\\Biki\\anaconda3\\envs\\venv1\\lib\\site-packages\\keras\\engine\\training.py\", line 1557, in test_function\n      return step_function(self, iterator)\n    File \"c:\\Users\\Biki\\anaconda3\\envs\\venv1\\lib\\site-packages\\keras\\engine\\training.py\", line 1546, in step_function\n      outputs = model.distribute_strategy.run(run_step, args=(data,))\n    File \"c:\\Users\\Biki\\anaconda3\\envs\\venv1\\lib\\site-packages\\keras\\engine\\training.py\", line 1535, in run_step\n      outputs = model.test_step(data)\n    File \"c:\\Users\\Biki\\anaconda3\\envs\\venv1\\lib\\site-packages\\keras\\engine\\training.py\", line 1499, in test_step\n      y_pred = self(x, training=False)\n    File \"c:\\Users\\Biki\\anaconda3\\envs\\venv1\\lib\\site-packages\\keras\\utils\\traceback_utils.py\", line 64, in error_handler\n      return fn(*args, **kwargs)\n    File \"c:\\Users\\Biki\\anaconda3\\envs\\venv1\\lib\\site-packages\\keras\\engine\\training.py\", line 490, in __call__\n      return super().__call__(*args, **kwargs)\n    File \"c:\\Users\\Biki\\anaconda3\\envs\\venv1\\lib\\site-packages\\keras\\utils\\traceback_utils.py\", line 64, in error_handler\n      return fn(*args, **kwargs)\n    File \"c:\\Users\\Biki\\anaconda3\\envs\\venv1\\lib\\site-packages\\keras\\engine\\base_layer.py\", line 1014, in __call__\n      outputs = call_fn(inputs, *args, **kwargs)\n    File \"c:\\Users\\Biki\\anaconda3\\envs\\venv1\\lib\\site-packages\\keras\\utils\\traceback_utils.py\", line 92, in error_handler\n      return fn(*args, **kwargs)\n    File \"c:\\Users\\Biki\\anaconda3\\envs\\venv1\\lib\\site-packages\\keras\\engine\\functional.py\", line 458, in call\n      return self._run_internal_graph(\n    File \"c:\\Users\\Biki\\anaconda3\\envs\\venv1\\lib\\site-packages\\keras\\engine\\functional.py\", line 596, in _run_internal_graph\n      outputs = node.layer(*args, **kwargs)\n    File \"c:\\Users\\Biki\\anaconda3\\envs\\venv1\\lib\\site-packages\\keras\\utils\\traceback_utils.py\", line 64, in error_handler\n      return fn(*args, **kwargs)\n    File \"c:\\Users\\Biki\\anaconda3\\envs\\venv1\\lib\\site-packages\\keras\\engine\\base_layer.py\", line 1014, in __call__\n      outputs = call_fn(inputs, *args, **kwargs)\n    File \"c:\\Users\\Biki\\anaconda3\\envs\\venv1\\lib\\site-packages\\keras\\utils\\traceback_utils.py\", line 92, in error_handler\n      return fn(*args, **kwargs)\n    File \"c:\\Users\\Biki\\anaconda3\\envs\\venv1\\lib\\site-packages\\keras\\layers\\convolutional\\base_conv.py\", line 250, in call\n      outputs = self.convolution_op(inputs, self.kernel)\n    File \"c:\\Users\\Biki\\anaconda3\\envs\\venv1\\lib\\site-packages\\keras\\layers\\convolutional\\base_conv.py\", line 225, in convolution_op\n      return tf.nn.convolution(\nNode: 'model/block1_conv1/Conv2D'\nNo algorithm worked!  Error messages:\n  Profiling failure on CUDNN engine 1#TC: UNKNOWN: CUDNN_STATUS_EXECUTION_FAILED\nin tensorflow/stream_executor/cuda/cuda_dnn.cc(4031): 'cudnnConvolutionForward( cudnn.handle(), alpha, input_nd_.handle(), input_data.opaque(), filter_.handle(), filter_data.opaque(), conv_.handle(), ToConvForwardAlgo(algo), scratch_memory.opaque(), scratch_memory.size(), beta, output_nd_.handle(), output_data.opaque())'\n  Profiling failure on CUDNN engine 1: UNKNOWN: CUDNN_STATUS_EXECUTION_FAILED\nin tensorflow/stream_executor/cuda/cuda_dnn.cc(4031): 'cudnnConvolutionForward( cudnn.handle(), alpha, input_nd_.handle(), input_data.opaque(), filter_.handle(), filter_data.opaque(), conv_.handle(), ToConvForwardAlgo(algo), scratch_memory.opaque(), scratch_memory.size(), beta, output_nd_.handle(), output_data.opaque())'\n  Profiling failure on CUDNN engine 0#TC: UNKNOWN: CUDNN_STATUS_EXECUTION_FAILED\nin tensorflow/stream_executor/cuda/cuda_dnn.cc(4031): 'cudnnConvolutionForward( cudnn.handle(), alpha, input_nd_.handle(), input_data.opaque(), filter_.handle(), filter_data.opaque(), conv_.handle(), ToConvForwardAlgo(algo), scratch_memory.opaque(), scratch_memory.size(), beta, output_nd_.handle(), output_data.opaque())'\n  Profiling failure on CUDNN engine 0: UNKNOWN: CUDNN_STATUS_EXECUTION_FAILED\nin tensorflow/stream_executor/cuda/cuda_dnn.cc(4031): 'cudnnConvolutionForward( cudnn.handle(), alpha, input_nd_.handle(), input_data.opaque(), filter_.handle(), filter_data.opaque(), conv_.handle(), ToConvForwardAlgo(algo), scratch_memory.opaque(), scratch_memory.size(), beta, output_nd_.handle(), output_data.opaque())'\n  Profiling failure on CUDNN engine 2#TC: UNKNOWN: CUDNN_STATUS_EXECUTION_FAILED\nin tensorflow/stream_executor/cuda/cuda_dnn.cc(4031): 'cudnnConvolutionForward( cudnn.handle(), alpha, input_nd_.handle(), input_data.opaque(), filter_.handle(), filter_data.opaque(), conv_.handle(), ToConvForwardAlgo(algo), scratch_memory.opaque(), scratch_memory.size(), beta, output_nd_.handle(), output_data.opaque())'\n  Profiling failure on CUDNN engine 2: UNKNOWN: CUDNN_STATUS_EXECUTION_FAILED\nin tensorflow/stream_executor/cuda/cuda_dnn.cc(4031): 'cudnnConvolutionForward( cudnn.handle(), alpha, input_nd_.handle(), input_data.opaque(), filter_.handle(), filter_data.opaque(), conv_.handle(), ToConvForwardAlgo(algo), scratch_memory.opaque(), scratch_memory.size(), beta, output_nd_.handle(), output_data.opaque())'\n  Profiling failure on CUDNN engine 4#TC: UNKNOWN: CUDNN_STATUS_EXECUTION_FAILED\nin tensorflow/stream_executor/cuda/cuda_dnn.cc(4031): 'cudnnConvolutionForward( cudnn.handle(), alpha, input_nd_.handle(), input_data.opaque(), filter_.handle(), filter_data.opaque(), conv_.handle(), ToConvForwardAlgo(algo), scratch_memory.opaque(), scratch_memory.size(), beta, output_nd_.handle(), output_data.opaque())'\n  Profiling failure on CUDNN engine 4: UNKNOWN: CUDNN_STATUS_EXECUTION_FAILED\nin tensorflow/stream_executor/cuda/cuda_dnn.cc(4031): 'cudnnConvolutionForward( cudnn.handle(), alpha, input_nd_.handle(), input_data.opaque(), filter_.handle(), filter_data.opaque(), conv_.handle(), ToConvForwardAlgo(algo), scratch_memory.opaque(), scratch_memory.size(), beta, output_nd_.handle(), output_data.opaque())'\n  Profiling failure on CUDNN engine 6#TC: UNKNOWN: CUDNN_STATUS_EXECUTION_FAILED\nin tensorflow/stream_executor/cuda/cuda_dnn.cc(4031): 'cudnnConvolutionForward( cudnn.handle(), alpha, input_nd_.handle(), input_data.opaque(), filter_.handle(), filter_data.opaque(), conv_.handle(), ToConvForwardAlgo(algo), scratch_memory.opaque(), scratch_memory.size(), beta, output_nd_.handle(), output_data.opaque())'\n  Profiling failure on CUDNN engine 6: UNKNOWN: CUDNN_STATUS_EXECUTION_FAILED\nin tensorflow/stream_executor/cuda/cuda_dnn.cc(4031): 'cudnnConvolutionForward( cudnn.handle(), alpha, input_nd_.handle(), input_data.opaque(), filter_.handle(), filter_data.opaque(), conv_.handle(), ToConvForwardAlgo(algo), scratch_memory.opaque(), scratch_memory.size(), beta, output_nd_.handle(), output_data.opaque())'\n  Profiling failure on CUDNN engine 5#TC: UNKNOWN: CUDNN_STATUS_INTERNAL_ERROR\nin tensorflow/stream_executor/cuda/cuda_dnn.cc(4031): 'cudnnConvolutionForward( cudnn.handle(), alpha, input_nd_.handle(), input_data.opaque(), filter_.handle(), filter_data.opaque(), conv_.handle(), ToConvForwardAlgo(algo), scratch_memory.opaque(), scratch_memory.size(), beta, output_nd_.handle(), output_data.opaque())'\n  Profiling failure on CUDNN engine 5: UNKNOWN: CUDNN_STATUS_INTERNAL_ERROR\nin tensorflow/stream_executor/cuda/cuda_dnn.cc(4031): 'cudnnConvolutionForward( cudnn.handle(), alpha, input_nd_.handle(), input_data.opaque(), filter_.handle(), filter_data.opaque(), conv_.handle(), ToConvForwardAlgo(algo), scratch_memory.opaque(), scratch_memory.size(), beta, output_nd_.handle(), output_data.opaque())'\n  Profiling failure on CUDNN engine 7#TC: UNKNOWN: CUDNN_STATUS_EXECUTION_FAILED\nin tensorflow/stream_executor/cuda/cuda_dnn.cc(4031): 'cudnnConvolutionForward( cudnn.handle(), alpha, input_nd_.handle(), input_data.opaque(), filter_.handle(), filter_data.opaque(), conv_.handle(), ToConvForwardAlgo(algo), scratch_memory.opaque(), scratch_memory.size(), beta, output_nd_.handle(), output_data.opaque())'\n  Profiling failure on CUDNN engine 7: UNKNOWN: CUDNN_STATUS_EXECUTION_FAILED\nin tensorflow/stream_executor/cuda/cuda_dnn.cc(4031): 'cudnnConvolutionForward( cudnn.handle(), alpha, input_nd_.handle(), input_data.opaque(), filter_.handle(), filter_data.opaque(), conv_.handle(), ToConvForwardAlgo(algo), scratch_memory.opaque(), scratch_memory.size(), beta, output_nd_.handle(), output_data.opaque())'\n\t [[{{node model/block1_conv1/Conv2D}}]] [Op:__inference_test_function_912]"
     ]
    }
   ],
   "source": [
    "test_loss, test_accuracy = model.evaluate(test_set, steps=len(test_set), batch_size=8)"
   ]
  },
  {
   "cell_type": "code",
   "execution_count": null,
   "metadata": {},
   "outputs": [],
   "source": [
    "predictions = model.predict(test_set, steps=len(test_set))"
   ]
  },
  {
   "cell_type": "code",
   "execution_count": null,
   "metadata": {},
   "outputs": [],
   "source": [
    "true_labels = test_set.classes\n"
   ]
  },
  {
   "cell_type": "code",
   "execution_count": null,
   "metadata": {},
   "outputs": [],
   "source": [
    "predicted_labels = np.argmax(predictions, axis=1)"
   ]
  },
  {
   "cell_type": "code",
   "execution_count": null,
   "metadata": {},
   "outputs": [],
   "source": [
    "report = classification_report(true_labels, predicted_labels, target_names=test_set.class_indices.keys())\n",
    "confusion = confusion_matrix(true_labels, predicted_labels)\n",
    "\n",
    "# Print the test accuracy and other metrics\n",
    "print(f'Test Loss: {test_loss:.4f}')\n",
    "print(f'Test Accuracy: {test_accuracy:.4f}')\n",
    "print('\\nClassification Report:\\n', report)\n",
    "print('\\nConfusion Matrix:\\n', confusion)"
   ]
  }
 ],
 "metadata": {
  "kernelspec": {
   "display_name": "venv1",
   "language": "python",
   "name": "python3"
  },
  "language_info": {
   "codemirror_mode": {
    "name": "ipython",
    "version": 3
   },
   "file_extension": ".py",
   "mimetype": "text/x-python",
   "name": "python",
   "nbconvert_exporter": "python",
   "pygments_lexer": "ipython3",
   "version": "3.9.0"
  },
  "orig_nbformat": 4
 },
 "nbformat": 4,
 "nbformat_minor": 2
}
